Workbook
Name ci_alpha: #REF!
Name conf_level: #REF!
Name n_iter: #REF!
Name year_mon: #REF!
Name year_ref: #REF!

Sheet user_input_details
A1: input_name | B1: input_description
A2: trunc_pdf | B2: Use truncated distributions to avoid negative values were illogical (TRUE or FALSE)
A3: n_iter | B3: How many simulations (Default 10,000)
A4: ran_seed | B4: Use a seed to reproduce random simulations (recommend setting to NULL the first time)
A5: c_unit | B5: What is the unit of AGB and BGB if included (DM for dry matter or C for carbon)
A6: c_fraction | B6: Carbon fraction value, mandatory if c_unit is "DM"
A7: c_fraction_se | B7: Carbon fraction standard error, mandatory if c_unit is "DM"
A8: c_fraction_pdf | B8: Carbon fraction PDF, mandatory if c_unit is "DM"
A9: dg_ext | B9: extension for degradation land use (ex. "_deg") for the code to identify degradaed LU and their corresponding intact class
A10: dg_pool | B10: If degradation is a ratio of intact forest Cstock, list of pools separated by coma. Any combination of AGB, BGB, DW, LI, SOC or NA if not applicable. Note: the pools not listed in dg_pool will be excluded when calculating the initial vs final Cstocks
A11: ad_annual | B11: Is AD reported in ha/year or in ha (TRUE or FALSE resp.)
A12: conf_level | B12: Confidence level (1 - alpha) between 0 and 1

Sheet user_inputs
A1: trunc_pdf | B1: n_iter | C1: ran_seed | D1: c_unit | E1: c_fraction | F1: c_fraction_se | G1: c_fraction_pdf | H1: dg_ext | I1: dg_pool | J1: ad_annual | K1: conf_level | L1: round_digits
A2: FALSE | B2: 10000 | C2: NA | D2: DM | E2: 0.47 | F2: 0.013 | G2: normal | H2: _deg | I2: ALL | J2: FALSE | K2: 0.9 | L2: 3

Sheet time_periods
A1: period_no | B1: year_start | C1: year_end | D1: period_type
A2: T1 | B2: 2017 | C2: 2017 | D2: REF
A3: T2 | B3: 2018 | C3: 2018 | D3: REF
A4: T3 | B4: 2019 | C4: 2019 | D4: REF
A5: T4 | B5: 2020 | C5: 2020 | D5: REF
A6: T5 | B6: 2021 | C6: 2021 | D6: REF
A7: T6 | B7: 2022 | C7: 2022 | D7: MON1
A8: T7 | B8: 2023 | C8: 2023 | D8: MON1
A9: T8 | B9: 2024 | C9: 2024 | D9: MON1

Sheet AD_lu_transitions
A1: trans_no | B1: trans_id | C1: trans_period | D1: trans_placeholder | E1: lu_initial_id | F1: lu_final_id | G1: trans_area | H1: trans_se | I1: trans_pdf | J1: trans_pdf_a | K1: trans_pdf_b | L1: trans_pdf_c | M1: lu_initial | N1: lu_final | O1: redd_activity
A2: 1 | B2: =C2&"_"&E2&"_"&F2 -> T1_FPc_NF | C2: T1 | E2: FPc | F2: NF | G2: 0 | H2: 0 | I2: normal | M2: =VLOOKUP(E2,'LU CLASS'!$B$2:$C$8,2,FALSE) -> Plantations commercial | N2: =VLOOKUP(F2,'LU CLASS'!$B$2:$C$8,2,FALSE) -> Non Forest | O2: DF
A3: 2 | B3: =C3&"_"&E3&"_"&F3 -> T1_FPnc_NF | C3: T1 | E3: FPnc | F3: NF | G3: 0 | H3: 0 | I3: normal | M3: =VLOOKUP(E3,'LU CLASS'!$B$2:$C$8,2,FALSE) -> Plantations non commercial | N3: =VLOOKUP(F3,'LU CLASS'!$B$2:$C$8,2,FALSE) -> Non Forest | O3: DF
A4: 3 | B4: =C4&"_"&E4&"_"&F4 -> T1_THF_NF | C4: T1 | E4: THF | F4: NF | G4: 5545.2056 | H4: 0.000120534 | I4: normal | M4: =VLOOKUP(E4,'LU CLASS'!$B$2:$C$8,2,FALSE) -> Tropical High Forest | N4: =VLOOKUP(F4,'LU CLASS'!$B$2:$C$8,2,FALSE) -> Non Forest | O4: DF
A5: 4 | B5: =C5&"_"&E5&"_"&F5 -> T1_WD_NF | C5: T1 | E5: WD | F5: NF | G5: 31228.544 | H5: 0.00038460972 | I5: normal | M5: =VLOOKUP(E5,'LU CLASS'!$B$2:$C$8,2,FALSE) -> Woodlands | N5: =VLOOKUP(F5,'LU CLASS'!$B$2:$C$8,2,FALSE) -> Non Forest | O5: DF
A6: 5 | B6: =C6&"_"&E6&"_"&F6 -> T1_THF_THF_deg | C6: T1 | E6: THF | F6: THF_deg | G6: 1109.0411 | H6: 5.3981232e-05 | I6: normal | M6: =VLOOKUP(E6,'LU CLASS'!$B$2:$C$8,2,FALSE) -> Tropical High Forest | N6: =VLOOKUP(F6,'LU CLASS'!$B$2:$C$8,2,FALSE) -> Tropical High Forest Degraded | O6: DG
A7: 6 | B7: =C7&"_"&E7&"_"&F7 -> T1_WD_WD_deg | C7: T1 | E7: WD | F7: WD_deg | G7: 6992.72 | H7: 0.00019856574 | I7: normal | M7: =VLOOKUP(E7,'LU CLASS'!$B$2:$C$8,2,FALSE) -> Woodlands | N7: =VLOOKUP(F7,'LU CLASS'!$B$2:$C$8,2,FALSE) -> Woodlands_Degraded | O7: DG
A8: 7 | B8: =C8&"_"&E8&"_"&F8 -> T2_FPc_NF | C8: T2 | E8: FPc | F8: NF | G8: 1109.0411 | H8: 5.3981232e-05 | I8: normal | M8: =VLOOKUP(E8,'LU CLASS'!$B$2:$C$8,2,FALSE) -> Plantations commercial | N8: =VLOOKUP(F8,'LU CLASS'!$B$2:$C$8,2,FALSE) -> Non Forest | O8: DF
A9: 8 | B9: =C9&"_"&E9&"_"&F9 -> T2_FPnc_NF | C9: T2 | E9: FPnc | F9: NF | G9: 1109.0411 | H9: 5.3981232e-05 | I9: normal | M9: =VLOOKUP(E9,'LU CLASS'!$B$2:$C$8,2,FALSE) -> Plantations non commercial | N9: =VLOOKUP(F9,'LU CLASS'!$B$2:$C$8,2,FALSE) -> Non Forest | O9: DF
A10: 9 | B10: =C10&"_"&E10&"_"&F10 -> T2_THF_NF | C10: T2 | E10: THF | F10: NF | G10: 6284.113 | H10: 0.00014043305 | I10: normal | M10: =VLOOKUP(E10,'LU CLASS'!$B$2:$C$8,2,FALSE) -> Tropical High Forest | N10: =VLOOKUP(F10,'LU CLASS'!$B$2:$C$8,2,FALSE) -> Non Forest | O10: DF
A11: 10 | B11: =C11&"_"&E11&"_"&F11 -> T2_WD_NF | C11: T2 | E11: WD | F11: NF | G11: 61205.496 | H11: 0.00051335037 | I11: normal | M11: =VLOOKUP(E11,'LU CLASS'!$B$2:$C$8,2,FALSE) -> Woodlands | N11: =VLOOKUP(F11,'LU CLASS'!$B$2:$C$8,2,FALSE) -> Non Forest | O11: DF
A12: 11 | B12: =C12&"_"&E12&"_"&F12 -> T2_THF_THF_deg | C12: T2 | E12: THF | F12: THF_deg | G12: 3327.1234 | H12: 9.3431761e-05 | I12: normal | M12: =VLOOKUP(E12,'LU CLASS'!$B$2:$C$8,2,FALSE) -> Tropical High Forest | N12: =VLOOKUP(F12,'LU CLASS'!$B$2:$C$8,2,FALSE) -> Tropical High Forest Degraded | O12: DG
A13: 12 | B13: =C13&"_"&E13&"_"&F13 -> T2_WD_WD_deg | C13: T2 | E13: WD | F13: WD_deg | G13: 11097.163 | H13: 0.00023169461 | I13: normal | M13: =VLOOKUP(E13,'LU CLASS'!$B$2:$C$8,2,FALSE) -> Woodlands | N13: =VLOOKUP(F13,'LU CLASS'!$B$2:$C$8,2,FALSE) -> Woodlands_Degraded | O13: DG
... A49: 48 | B49: =C49&"_"&E49&"_"&F49 -> T8_WD_WD_deg | C49: T8 | E49: WD | F49: WD_deg | G49: 6549.4934 | H49: 0.0002135017 | I49: normal | M49: =VLOOKUP(E49,'LU CLASS'!$B$2:$C$8,2,FALSE) -> Woodlands | N49: =VLOOKUP(F49,'LU CLASS'!$B$2:$C$8,2,FALSE) -> Woodlands_Degraded | O49: DG

Sheet c_stocks
A1: c_no | B1: c_id | C1: c_period | D1: c_element | E1: c_lu_id | F1: c_placeholder | G1: c_value | H1: c_se | I1: c_pdf | J1: c_pdf_a | K1: c_pdf_b | L1: c_pdf_c | M1: c_lu_name
A2: 1 | B2: =C2&"_"&D2&"_"&E2 -> ALL_AGB_THF | C2: ALL | D2: AGB | E2: THF | G2: 348 | H2: 4.2439024 | I2: normal | M2: =VLOOKUP(E2,'LU CLASS'!$B$2:$C$8,2,FALSE) -> Tropical High Forest
A3: 2 | B3: =C3&"_"&D3&"_"&E3 -> ALL_AGB_THF_deg | C3: ALL | D3: AGB | E3: THF_deg | G3: 232.3 | H3: 2.8329268 | I3: normal | M3: =VLOOKUP(E3,'LU CLASS'!$B$2:$C$8,2,FALSE) -> Tropical High Forest Degraded
A4: 3 | B4: =C4&"_"&D4&"_"&E4 -> ALL_AGB_WD | C4: ALL | D4: AGB | E4: WD | G4: 16.5 | H4: 7.5457317 | I4: normal | M4: =VLOOKUP(E4,'LU CLASS'!$B$2:$C$8,2,FALSE) -> Woodlands
A5: 4 | B5: =C5&"_"&D5&"_"&E5 -> ALL_AGB_WD_deg | C5: ALL | D5: AGB | E5: WD_deg | G5: 14.8 | H5: 6.7682927 | I5: normal | M5: =VLOOKUP(E5,'LU CLASS'!$B$2:$C$8,2,FALSE) -> Woodlands_Degraded
A6: 5 | B6: =C6&"_"&D6&"_"&E6 -> ALL_AGB_FPc | C6: ALL | D6: AGB | E6: FPc | G6: 81.7 | H6: 73.729268 | I6: normal | M6: =VLOOKUP(E6,'LU CLASS'!$B$2:$C$8,2,FALSE) -> Plantations commercial
A7: 6 | B7: =C7&"_"&D7&"_"&E7 -> ALL_AGB_FPnc | C7: ALL | D7: AGB | E7: FPnc | G7: 81.7 | H7: 73.729268 | I7: normal | M7: =VLOOKUP(E7,'LU CLASS'!$B$2:$C$8,2,FALSE) -> Plantations non commercial
A8: 7 | B8: =C8&"_"&D8&"_"&E8 -> ALL_ALL_NF | C8: ALL | D8: ALL | E8: NF | G8: 21 | H8: 9.6036585 | I8: normal | M8: =VLOOKUP(E8,'LU CLASS'!$B$2:$C$8,2,FALSE) -> Non Forest
A9: 8 | B9: =C9&"_"&D9&"_"&E9 -> ALL_RS_THF | C9: ALL | D9: RS | E9: THF | G9: 0.24 | H9: 0.055 | I9: normal | M9: =VLOOKUP(E9,'LU CLASS'!$B$2:$C$8,2,FALSE) -> Tropical High Forest
A10: 9 | B10: =C10&"_"&D10&"_"&E10 -> ALL_RS_THF_deg | C10: ALL | D10: RS | E10: THF_deg | G10: 0.24 | H10: 0.055 | I10: normal | M10: =VLOOKUP(E10,'LU CLASS'!$B$2:$C$8,2,FALSE) -> Tropical High Forest Degraded
A11: 10 | B11: =C11&"_"&D11&"_"&E11 -> ALL_RS_WD | C11: ALL | D11: RS | E11: WD | G11: 0.24 | H11: 0.055 | I11: normal | M11: =VLOOKUP(E11,'LU CLASS'!$B$2:$C$8,2,FALSE) -> Woodlands
A12: 11 | B12: =C12&"_"&D12&"_"&E12 -> ALL_RS_WD_deg | C12: ALL | D12: RS | E12: WD_deg | G12: 0.24 | H12: 0.055 | I12: normal | M12: =VLOOKUP(E12,'LU CLASS'!$B$2:$C$8,2,FALSE) -> Woodlands_Degraded
A13: 12 | B13: =C13&"_"&D13&"_"&E13 -> ALL_RS_FPc | C13: ALL | D13: RS | E13: FPc | G13: 0.24 | H13: 0.055 | I13: normal | M13: =VLOOKUP(E13,'LU CLASS'!$B$2:$C$8,2,FALSE) -> Plantations commercial
A14: 13 | B14: =C14&"_"&D14&"_"&E14 -> ALL_RS_FPnc | C14: ALL | D14: RS | E14: FPnc | G14: 0.24 | H14: 0.055 | I14: normal | M14: =VLOOKUP(E14,'LU CLASS'!$B$2:$C$8,2,FALSE) -> Plantations non commercial

Sheet Cstocks_prep
A1: c_no | B1: c_id | C1: c_period | D1: c_element | E1: c_lu_id | F1: c_placeholder | G1: c_value | H1: c_se | I1: c_pdf | J1: c_pdf_a | K1: c_pdf_b | L1: c_pdf_c | M1: c_lu_name
A2: 1 | B2: ALL_AGB_EV | C2: ALL | D2: AGB | E2: THF | G2: 348 | H2: =2*G2/1.64/100 -> 4.2439024 | I2: normal
A3: 2 | B3: ALL_AGB_M | C3: ALL | D3: AGB | E3: THF_deg | G3: 232.3 | H3: =2*G3/1.64/100 -> 2.8329268 | I3: normal
A4: 3 | B4: ALL_RS_EV | C4: ALL | D4: AGB | E4: WD | G4: 16.5 | H4: =75*G4/1.64/100 -> 7.5457317 | I4: normal
A5: 4 | B5: ALL_RS_M | C5: ALL | D5: AGB | E5: WD_deg | G5: 14.8 | H5: =75*G5/1.64/100 -> 6.7682927 | I5: normal
A6: 5 | B6: ALL_DG_ratio_EV_deg | C6: ALL | D6: AGB | E6: FPc | G6: 81.7 | H6: =148*G6/1.64/100 -> 73.729268 | I6: normal
A7: 6 | B7: ALL_DG_ratio_M_deg | C7: ALL | D7: AGB | E7: FPnc | G7: 81.7 | H7: =148*G7/1.64/100 -> 73.729268 | I7: normal
A8: 7 | B8: ALL_ALL_Crop | C8: ALL | D8: ALL | E8: NF | G8: 21 | H8: =75*G8/1.64/100 -> 9.6036585 | I8: normal
D9: RS | E9: THF | G9: 0.24 | H9: =(-0.22 + 0.33)/2 -> 0.055 | I9: normal
D10: RS | E10: THF_deg | G10: 0.24 | H10: =(-0.22 + 0.33)/2 -> 0.055 | I10: normal
D11: RS | E11: WD | G11: 0.24 | H11: =(-0.22 + 0.33)/2 -> 0.055 | I11: normal
D12: RS | E12: WD_deg | G12: 0.24 | H12: =(-0.22 + 0.33)/2 -> 0.055 | I12: normal
D13: RS | E13: FPc | G13: 0.24 | H13: =(-0.22 + 0.33)/2 -> 0.055 | I13: normal
D14: RS | E14: FPnc | G14: 0.24 | H14: =(-0.22 + 0.33)/2 -> 0.055 | I14: normal

Sheet AD_Prep
A1: transition | B1: time_period | C1: lu_initial | D1: lu_final | E1: area_ha_2017 | F1: SE2017 | G1: year
A2: Deforestation_in_Forest_Plantations: commercial | B2: T1 | C2: FPc | D2: NF | E2: 0 | F2: 0 | G2: 2017
A3: Deforestation_in_Forest_Plantations: non commercial | B3: T1 | C3: FPnc | D3: NF | E3: 0 | F3: 0 | G3: 2017
A4: Deforestation_in_THF | B4: T1 | C4: THF | D4: NF | E4: 5545.2056 | F4: 0.000120534 | G4: 2017
A5: Deforestation_in_Woodlands | B5: T1 | C5: WD | D5: NF | E5: 31228.544 | F5: 0.00038460972 | G5: 2017
A6: Degradation_in_THF | B6: T1 | C6: THF | D6: THF_Deg | E6: 1109.0411 | F6: 5.3981232e-05 | G6: 2017
A7: Degradation_in_Woodlands | B7: T1 | C7: WD | D7: WD_Deg | E7: 6992.72 | F7: 0.00019856574 | G7: 2017
C8: FPc | D8: NF | E8: 1109.0411 | F8: 5.3981232e-05
A9: Deforestation_in_Forest_Plantations: commercial | B9: T2 | C9: FPnc | D9: NF | E9: 1109.0411 | F9: 5.3981232e-05 | G9: 2018
A10: Deforestation_in_Forest_Plantations: non commercial | B10: T2 | C10: THF | D10: NF | E10: 6284.113 | F10: 0.00014043305 | G10: 2018
A11: Deforestation_in_THF | B11: T2 | C11: WD | D11: NF | E11: 61205.496 | F11: 0.00051335037 | G11: 2018
A12: Deforestation_in_Woodlands | B12: T2 | C12: THF | D12: THF_Deg | E12: 3327.1234 | F12: 9.3431761e-05 | G12: 2018
A13: Degradation_in_THF | B13: T2 | C13: WD | D13: WD_Deg | E13: 11097.163 | F13: 0.00023169461 | G13: 2018
A14: Degradation_in_Woodlands | B14: T2 | C14: FPc | D14: NF | E14: 2572.3858 | F14: 0.00012520776 | G14: 2018
C15: FPnc | D15: NF | E15: 4804.9382 | F15: 0.00013814264
C16: THF | D16: NF | E16: 1109.0411 | F16: 5.3981232e-05
A17: Deforestation_in_Forest_Plantations: commercial | B17: T3 | C17: WD | D17: NF | E17: 25444.625 | F17: 0.00033943477 | G17: 2019
A18: Deforestation_in_Forest_Plantations: non commercial | B18: T3 | C18: THF | D18: THF_Deg | E18: 0 | F18: 0 | G18: 2019
A19: Deforestation_in_THF | B19: T3 | C19: WD | D19: WD_Deg | E19: 8116.2314 | F19: 0.00019978495 | G19: 2019
A20: Deforestation_in_Woodlands | B20: T3 | C20: FPc | D20: NF | E20: 1109.0411 | F20: 5.3981232e-05 | G20: 2019
A21: Degradation_in_THF | B21: T3 | C21: FPnc | D21: NF | E21: 4066.0308 | F21: 0.00011795849 | G21: 2019
A22: Degradation_in_Woodlands | B22: T3 | C22: THF | D22: NF | E22: 2218.0822 | F22: 7.6313857e-05 | G22: 2019
C23: WD | D23: NF | E23: 46165.159 | F23: 0.00049574745
A24: Deforestation_in_Forest_Plantations: commercial | B24: T4 | C24: THF | D24: THF_Deg | E24: 1847.9485 | F24: 8.9946656e-05 | G24: 2020
A25: Deforestation_in_Forest_Plantations: non commercial | B25: T4 | C25: WD | D25: WD_Deg | E25: 5990.8033 | F25: 0.00015058274 | G25: 2020
A26: Deforestation_in_THF | B26: T4 | C26: FPc | D26: NF | E26: 2218.0822 | F26: 7.6313857e-05 | G26: 2020
A27: Deforestation_in_Woodlands | B27: T4 | C27: FPnc | D27: NF | E27: 3327.1234 | G27: 2020
A28: Degradation_in_THF | B28: T4 | C28: THF | D28: NF | E28: 5913.9793 | G28: 2020
A29: Degradation_in_Woodlands | B29: T4 | C29: WD | D29: NF | E29: 44026.236 | G29: 2020
C30: THF | D30: THF_Deg | E30: 0
A31: Deforestation_in_Forest_Plantations: commercial | B31: T5 | C31: WD | D31: WD_Deg | E31: 12259.086 | G31: 2021
A32: Deforestation_in_Forest_Plantations: non commercial | B32: T5 | C32: FPc | D32: NF | E32: 1109.0411 | F32: 5.3981232e-05 | G32: 2021
A33: Deforestation_in_THF | B33: T5 | C33: FPnc | D33: NF | E33: 4436.1645 | F33: 0.0001078473 | G33: 2021
A34: Deforestation_in_Woodlands | B34: T5 | C34: THF | D34: NF | E34: 4436.1645 | F34: 0.0001078473 | G34: 2021
A35: Degradation_in_THF | B35: T5 | C35: WD | D35: NF | E35: 27937.95 | F35: 0.00032563474 | G35: 2021
A36: Degradation_in_Woodlands | B36: T5 | C36: THF | D36: THF_Deg | E36: 0 | F36: 0 | G36: 2021
C37: WD | D37: WD_Deg | E37: 9374.0513 | F37: 0.00023023414
A38: Deforestation_in_Forest_Plantations: commercial | B38: T6 | C38: FPc | D38: NF | E38: 8279.4804 | F38: 0.0002183682 | G38: 2022
A39: Deforestation_in_Forest_Plantations: non commercial | B39: T6 | C39: FPnc | D39: NF | E39: 1886.3605 | F39: 9.1816313e-05 | G39: 2022
A40: Deforestation_in_THF | B40: T6 | C40: THF | D40: NF | E40: 4104.4428 | F40: 0.00011939028 | G40: 2022
...

Sheet LU CLASS
B2: FPc | C2: Plantations commercial
B3: FPnc | C3: Plantations non commercial
B4: THF | C4: Tropical High Forest
B5: WD | C5: Woodlands
B6: THF_deg | C6: Tropical High Forest Degraded
B7: WD_deg | C7: Woodlands_Degraded
B8: NF | C8: Non Forest
